{
  "unit": 1,
  "voxel_size": 0.001,
  "mode": "model",
  "dims": [16, 16, 16],
  "voxels": [
    {"x":2,"y":2,"z":2,"mat":"sheet_metal","rgb":8028293},
    {"x":3,"y":2,"z":2,"mat":"sheet_metal","rgb":8028293},
    {"x":4,"y":2,"z":2,"mat":"sheet_metal","rgb":8028293},
    {"x":5,"y":2,"z":2,"mat":"sheet_metal","rgb":8028293},
    {"x":6,"y":2,"z":2,"mat":"sheet_metal","rgb":8028293},
    {"x":2,"y":2,"z":3,"mat":"sheet_metal","rgb":8028293},
    {"x":3,"y":2,"z":3,"mat":"sheet_metal","rgb":8028293},
    {"x":4,"y":2,"z":3,"mat":"sheet_metal","rgb":8028293},
    {"x":5,"y":2,"z":3,"mat":"sheet_metal","rgb":8028293},
    {"x":6,"y":2,"z":3,"mat":"sheet_metal","rgb":8028293},
    {"x":2,"y":2,"z":4,"mat":"sheet_metal","rgb":8028293},
    {"x":3,"y":2,"z":4,"mat":"sheet_metal","rgb":8028293},
    {"x":4,"y":2,"z":4,"mat":"sheet_metal","rgb":8028293},
    {"x":5,"y":2,"z":4,"mat":"sheet_metal","rgb":8028293},
    {"x":6,"y":2,"z":4,"mat":"sheet_metal","rgb":8028293},
    {"x":2,"y":2,"z":5,"mat":"sheet_metal","rgb":8028293},
    {"x":3,"y":2,"z":5,"mat":"sheet_metal","rgb":8028293},
    {"x":4,"y":2,"z":5,"mat":"sheet_metal","rgb":8028293},
    {"x":5,"y":2,"z":5,"mat":"sheet_metal","rgb":8028293},
    {"x":6,"y":2,"z":5,"mat":"sheet_metal","rgb":8028293},
    {"x":2,"y":2,"z":6,"mat":"sheet_metal","rgb":8028293},
    {"x":3,"y":2,"z":6,"mat":"sheet_metal","rgb":8028293},
    {"x":4,"y":2,"z":6,"mat":"sheet_metal","rgb":8028293},
    {"x":5,"y":2,"z":6,"mat":"sheet_metal","rgb":8028293},
    {"x":6,"y":2,"z":6,"mat":"sheet_metal","rgb":8028293},
    {"x":2,"y":3,"z":2,"mat":"sheet_metal","rgb":8028293},
    {"x":3,"y":3,"z":2,"mat":"sheet_metal","rgb":8028293},
    {"x":4,"y":3,"z":2,"mat":"sheet_metal","rgb":8028293},
    {"x":5,"y":3,"z":2,"mat":"sheet_metal","rgb":8028293},
    {"x":6,"y":3,"z":2,"mat":"sheet_metal","rgb":8028293},
    {"x":2,"y":3,"z":3,"mat":"sheet_metal","rgb":8028293},
    {"x":3,"y":3,"z":3,"mat":"sheet_metal","rgb":8028293},
    {"x":4,"y":3,"z":3,"mat":"sheet_metal","rgb":8028293},
    {"x":5,"y":3,"z":3,"mat":"sheet_metal","rgb":8028293},
    {"x":6,"y":3,"z":3,"mat":"sheet_metal","rgb":8028293},
    {"x":2,"y":3,"z":4,"mat":"sheet_metal","rgb":8028293},
    {"x":3,"y":3,"z":4,"mat":"sheet_metal","rgb":8028293},
    {"x":4,"y":3,"z":4,"mat":"sheet_metal","rgb":8028293},
    {"x":5,"y":3,"z":4,"mat":"sheet_metal","rgb":8028293},
    {"x":6,"y":3,"z":4,"mat":"sheet_metal","rgb":8028293},
    {"x":2,"y":3,"z":5,"mat":"sheet_metal","rgb":8028293},
    {"x":3,"y":3,"z":5,"mat":"sheet_metal","rgb":8028293},
    {"x":4,"y":3,"z":5,"mat":"sheet_metal","rgb":8028293},
    {"x":5,"y":3,"z":5,"mat":"sheet_metal","rgb":8028293},
    {"x":6,"y":3,"z":5,"mat":"sheet_metal","rgb":8028293},
    {"x":2,"y":3,"z":6,"mat":"sheet_metal","rgb":8028293},
    {"x":3,"y":3,"z":6,"mat":"sheet_metal","rgb":8028293},
    {"x":4,"y":3,"z":6,"mat":"sheet_metal","rgb":8028293},
    {"x":5,"y":3,"z":6,"mat":"sheet_metal","rgb":8028293},
    {"x":6,"y":3,"z":6,"mat":"sheet_metal","rgb":8028293},
    {"x":2,"y":4,"z":2,"mat":"sheet_metal","rgb":8028293},
    {"x":3,"y":4,"z":2,"mat":"sheet_metal","rgb":8028293},
    {"x":4,"y":4,"z":2,"mat":"sheet_metal","rgb":8028293},
    {"x":5,"y":4,"z":2,"mat":"sheet_metal","rgb":8028293},
    {"x":6,"y":4,"z":2,"mat":"sheet_metal","rgb":8028293},
    {"x":2,"y":4,"z":3,"mat":"sheet_metal","rgb":8028293},
    {"x":3,"y":4,"z":3,"mat":"sheet_metal","rgb":8028293},
    {"x":4,"y":4,"z":3,"mat":"sheet_metal","rgb":8028293},
    {"x":5,"y":4,"z":3,"mat":"sheet_metal","rgb":8028293},
    {"x":6,"y":4,"z":3,"mat":"sheet_metal","rgb":8028293},
    {"x":2,"y":4,"z":4,"mat":"sheet_metal","rgb":8028293},
    {"x":3,"y":4,"z":4,"mat":"sheet_metal","rgb":8028293},
    {"x":4,"y":4,"z":4,"mat":"wood","rgb":6710891},
    {"x":5,"y":4,"z":4,"mat":"wood","rgb":6710891},
    {"x":6,"y":4,"z":4,"mat":"sheet_metal","rgb":8028293},
    {"x":2,"y":4,"z":5,"mat":"sheet_metal","rgb":8028293},
    {"x":3,"y":4,"z":5,"mat":"sheet_metal","rgb":8028293},
    {"x":4,"y":4,"z":5,"mat":"wood","rgb":6710891},
    {"x":5,"y":4,"z":5,"mat":"wood","rgb":6710891},
    {"x":6,"y":4,"z":5,"mat":"sheet_metal","rgb":8028293},
    {"x":2,"y":4,"z":6,"mat":"sheet_metal","rgb":8028293},
    {"x":3,"y":4,"z":6,"mat":"sheet_metal","rgb":8028293},
    {"x":4,"y":4,"z":6,"mat":"sheet_metal","rgb":8028293},
    {"x":5,"y":4,"z":6,"mat":"sheet_metal","rgb":8028293},
    {"x":6,"y":4,"z":6,"mat":"sheet_metal","rgb":8028293},
    {"x":2,"y":5,"z":2,"mat":"sheet_metal","rgb":8028293},
    {"x":3,"y":5,"z":2,"mat":"sheet_metal","rgb":8028293},
    {"x":4,"y":5,"z":2,"mat":"sheet_metal","rgb":8028293},
    {"x":5,"y":5,"z":2,"mat":"sheet_metal","rgb":8028293},
    {"x":6,"y":5,"z":2,"mat":"sheet_metal","rgb":8028293},
    {"x":2,"y":5,"z":3,"mat":"sheet_metal","rgb":8028293},
    {"x":3,"y":5,"z":3,"mat":"sheet_metal","rgb":8028293},
    {"x":4,"y":5,"z":3,"mat":"sheet_metal","rgb":8028293},
    {"x":5,"y":5,"z":3,"mat":"sheet_metal","rgb":8028293},
    {"x":6,"y":5,"z":3,"mat":"sheet_metal","rgb":8028293},
    {"x":2,"y":5,"z":4,"mat":"sheet_metal","rgb":8028293},
    {"x":3,"y":5,"z":4,"mat":"sheet_metal","rgb":8028293},
    {"x":4,"y":5,"z":4,"mat":"wood","rgb":6710891},
    {"x":5,"y":5,"z":4,"mat":"wood","rgb":6710891},
    {"x":6,"y":5,"z":4,"mat":"sheet_metal","rgb":8028293},
    {"x":2,"y":5,"z":5,"mat":"sheet_metal","rgb":8028293},
    {"x":3,"y":5,"z":5,"mat":"sheet_metal","rgb":8028293},
    {"x":4,"y":5,"z":5,"mat":"wood","rgb":6710891},
    {"x":5,"y":5,"z":5,"mat":"wood","rgb":6710891},
    {"x":6,"y":5,"z":5,"mat":"sheet_metal","rgb":8028293},
    {"x":2,"y":5,"z":6,"mat":"sheet_metal","rgb":8028293},
    {"x":3,"y":5,"z":6,"mat":"sheet_metal","rgb":8028293},
    {"x":4,"y":5,"z":6,"mat":"sheet_metal","rgb":8028293},
    {"x":5,"y":5,"z":6,"mat":"sheet_metal","rgb":8028293},
    {"x":6,"y":5,"z":6,"mat":"sheet_metal","rgb":8028293},
    {"x":2,"y":6,"z":2,"mat":"sheet_metal","rgb":8028293},
    {"x":3,"y":6,"z":2,"mat":"sheet_metal","rgb":8028293},
    {"x":4,"y":6,"z":2,"mat":"sheet_metal","rgb":8028293},
    {"x":5,"y":6,"z":2,"mat":"sheet_metal","rgb":8028293},
    {"x":6,"y":6,"z":2,"mat":"sheet_metal","rgb":8028293},
    {"x":2,"y":6,"z":3,"mat":"sheet_metal","rgb":8028293},
    {"x":3,"y":6,"z":3,"mat":"sheet_metal","rgb":8028293},
    {"x":4,"y":6,"z":3,"mat":"sheet_metal","rgb":8028293},
    {"x":5,"y":6,"z":3,"mat":"sheet_metal","rgb":8028293},
    {"x":6,"y":6,"z":3,"mat":"sheet_metal","rgb":8028293},
    {"x":2,"y":6,"z":4,"mat":"sheet_metal","rgb":8028293},
    {"x":3,"y":6,"z":4,"mat":"sheet_metal","rgb":8028293},
    {"x":4,"y":6,"z":4,"mat":"sheet_metal","rgb":8028293},
    {"x":5,"y":6,"z":4,"mat":"sheet_metal","rgb":8028293},
    {"x":6,"y":6,"z":4,"mat":"sheet_metal","rgb":8028293},
    {"x":2,"y":6,"z":5,"mat":"sheet_metal","rgb":8028293},
    {"x":3,"y":6,"z":5,"mat":"sheet_metal","rgb":8028293},
    {"x":4,"y":6,"z":5,"mat":"sheet_metal","rgb":8028293},
    {"x":5,"y":6,"z":5,"mat":"sheet_metal","rgb":8028293},
    {"x":6,"y":6,"z":5,"mat":"sheet_metal","rgb":8028293},
    {"x":2,"y":6,"z":6,"mat":"sheet_metal","rgb":8028293},
    {"x":3,"y":6,"z":6,"mat":"sheet_metal","rgb":8028293},
    {"x":4,"y":6,"z":6,"mat":"sheet_metal","rgb":8028293},
    {"x":5,"y":6,"z":6,"mat":"sheet_metal","rgb":8028293},
    {"x":6,"y":6,"z":6,"mat":"sheet_metal","rgb":8028293}
  ]
}
